Unauthorized: /api/write_data/1/
--- Logging error ---
--- Logging error ---
--- Logging error ---
Traceback (most recent call last):
  File "/usr/lib/python3.12/logging/__init__.py", line 1164, in emit
    self.flush()
  File "/usr/lib/python3.12/logging/__init__.py", line 1144, in flush
    self.stream.flush()
RuntimeError: reentrant call inside <_io.BufferedWriter name='/home/ubuntu/HeatExchanger_Only_IOT/gunicorn_error.log'>

During handling of the above exception, another exception occurred:

Traceback (most recent call last):
  File "/usr/lib/python3.12/logging/__init__.py", line 1164, in emit
    self.flush()
  File "/usr/lib/python3.12/logging/__init__.py", line 1144, in flush
    self.stream.flush()
RuntimeError: reentrant call inside <_io.BufferedWriter name='/home/ubuntu/HeatExchanger_Only_IOT/gunicorn_error.log'>

During handling of the above exception, another exception occurred:

Traceback (most recent call last):
  File "/usr/lib/python3.12/logging/__init__.py", line 1164, in emit
    self.flush()
  File "/usr/lib/python3.12/logging/__init__.py", line 1144, in flush
    self.stream.flush()
RuntimeError: reentrant call inside <_io.BufferedWriter name='/home/ubuntu/HeatExchanger_Only_IOT/gunicorn_error.log'>
Call stack:
  File "/home/ubuntu/HeatExchanger_Only_IOT/venv/bin/gunicorn", line 8, in <module>
    sys.exit(run())
  File "/home/ubuntu/HeatExchanger_Only_IOT/venv/lib/python3.12/site-packages/gunicorn/app/wsgiapp.py", line 67, in run
    WSGIApplication("%(prog)s [OPTIONS] [APP_MODULE]").run()
  File "/home/ubuntu/HeatExchanger_Only_IOT/venv/lib/python3.12/site-packages/gunicorn/app/base.py", line 236, in run
    super().run()
  File "/home/ubuntu/HeatExchanger_Only_IOT/venv/lib/python3.12/site-packages/gunicorn/app/base.py", line 72, in run
    Arbiter(self).run()
  File "/home/ubuntu/HeatExchanger_Only_IOT/venv/lib/python3.12/site-packages/gunicorn/arbiter.py", line 223, in run
    self.log.info("Handling signal: %s", signame)
  File "/home/ubuntu/HeatExchanger_Only_IOT/venv/lib/python3.12/site-packages/gunicorn/glogging.py", line 278, in info
    self.error_log.info(msg, *args, **kwargs)
  File "/usr/lib/python3.12/logging/__init__.py", line 1539, in info
    self._log(INFO, msg, args, **kwargs)
  File "/usr/lib/python3.12/logging/__init__.py", line 1684, in _log
    self.handle(record)
  File "/usr/lib/python3.12/logging/__init__.py", line 1700, in handle
    self.callHandlers(record)
  File "/usr/lib/python3.12/logging/__init__.py", line 1762, in callHandlers
    hdlr.handle(record)
  File "/usr/lib/python3.12/logging/__init__.py", line 1028, in handle
    self.emit(record)
  File "/usr/lib/python3.12/logging/__init__.py", line 1280, in emit
    StreamHandler.emit(self, record)
  File "/usr/lib/python3.12/logging/__init__.py", line 1164, in emit
    self.flush()
  File "/usr/lib/python3.12/logging/__init__.py", line 1144, in flush
    self.stream.flush()
  File "/home/ubuntu/HeatExchanger_Only_IOT/venv/lib/python3.12/site-packages/gunicorn/arbiter.py", line 242, in handle_chld
    self.reap_workers()
  File "/home/ubuntu/HeatExchanger_Only_IOT/venv/lib/python3.12/site-packages/gunicorn/arbiter.py", line 554, in reap_workers
    self.log.error(msg)
  File "/home/ubuntu/HeatExchanger_Only_IOT/venv/lib/python3.12/site-packages/gunicorn/glogging.py", line 272, in error
    self.error_log.error(msg, *args, **kwargs)
  File "/usr/lib/python3.12/logging/__init__.py", line 1568, in error
    self._log(ERROR, msg, args, **kwargs)
  File "/usr/lib/python3.12/logging/__init__.py", line 1684, in _log
    self.handle(record)
  File "/usr/lib/python3.12/logging/__init__.py", line 1700, in handle
    self.callHandlers(record)
  File "/usr/lib/python3.12/logging/__init__.py", line 1762, in callHandlers
    hdlr.handle(record)
  File "/usr/lib/python3.12/logging/__init__.py", line 1028, in handle
    self.emit(record)
  File "/usr/lib/python3.12/logging/__init__.py", line 1280, in emit
    StreamHandler.emit(self, record)
  File "/usr/lib/python3.12/logging/__init__.py", line 1168, in emit
    self.handleError(record)
  File "/usr/lib/python3.12/logging/__init__.py", line 1082, in handleError
    traceback.print_exception(t, v, tb, None, sys.stderr)
  File "/usr/lib/python3.12/traceback.py", line 124, in print_exception
    te = TracebackException(type(value), value, tb, limit=limit, compact=True)
  File "/usr/lib/python3.12/traceback.py", line 733, in __init__
    self.stack = StackSummary._extract_from_extended_frame_gen(
  File "/usr/lib/python3.12/traceback.py", line 424, in _extract_from_extended_frame_gen
    linecache.lazycache(filename, f.f_globals)
  File "/usr/lib/python3.12/linecache.py", line 165, in lazycache
    if not filename or (filename.startswith('<') and filename.endswith('>')):
  File "/home/ubuntu/HeatExchanger_Only_IOT/venv/lib/python3.12/site-packages/gunicorn/arbiter.py", line 242, in handle_chld
    self.reap_workers()
  File "/home/ubuntu/HeatExchanger_Only_IOT/venv/lib/python3.12/site-packages/gunicorn/arbiter.py", line 554, in reap_workers
    self.log.error(msg)
  File "/home/ubuntu/HeatExchanger_Only_IOT/venv/lib/python3.12/site-packages/gunicorn/glogging.py", line 272, in error
    self.error_log.error(msg, *args, **kwargs)
  File "/usr/lib/python3.12/logging/__init__.py", line 1568, in error
    self._log(ERROR, msg, args, **kwargs)
  File "/usr/lib/python3.12/logging/__init__.py", line 1684, in _log
    self.handle(record)
  File "/usr/lib/python3.12/logging/__init__.py", line 1700, in handle
    self.callHandlers(record)
  File "/usr/lib/python3.12/logging/__init__.py", line 1762, in callHandlers
    hdlr.handle(record)
  File "/usr/lib/python3.12/logging/__init__.py", line 1028, in handle
    self.emit(record)
  File "/usr/lib/python3.12/logging/__init__.py", line 1280, in emit
    StreamHandler.emit(self, record)
  File "/usr/lib/python3.12/logging/__init__.py", line 1168, in emit
    self.handleError(record)
  File "/usr/lib/python3.12/logging/__init__.py", line 1082, in handleError
    traceback.print_exception(t, v, tb, None, sys.stderr)
  File "/usr/lib/python3.12/traceback.py", line 124, in print_exception
    te = TracebackException(type(value), value, tb, limit=limit, compact=True)
  File "/usr/lib/python3.12/traceback.py", line 733, in __init__
    self.stack = StackSummary._extract_from_extended_frame_gen(
  File "/usr/lib/python3.12/traceback.py", line 438, in _extract_from_extended_frame_gen
    f.line
  File "/usr/lib/python3.12/traceback.py", line 323, in line
    self._line = linecache.getline(self.filename, self.lineno)
  File "/usr/lib/python3.12/linecache.py", line 30, in getline
    lines = getlines(filename, module_globals)
  File "/usr/lib/python3.12/linecache.py", line 46, in getlines
    return updatecache(filename, module_globals)
  File "/usr/lib/python3.12/linecache.py", line 93, in updatecache
    stat = os.stat(fullname)
  File "/home/ubuntu/HeatExchanger_Only_IOT/venv/lib/python3.12/site-packages/gunicorn/arbiter.py", line 242, in handle_chld
    self.reap_workers()
  File "/home/ubuntu/HeatExchanger_Only_IOT/venv/lib/python3.12/site-packages/gunicorn/arbiter.py", line 554, in reap_workers
    self.log.error(msg)
  File "/home/ubuntu/HeatExchanger_Only_IOT/venv/lib/python3.12/site-packages/gunicorn/glogging.py", line 272, in error
    self.error_log.error(msg, *args, **kwargs)
Message: 'Worker (pid:8545) was sent SIGHUP!'
Arguments: ()
Traceback (most recent call last):
  File "/usr/lib/python3.12/logging/__init__.py", line 1164, in emit
    self.flush()
  File "/usr/lib/python3.12/logging/__init__.py", line 1144, in flush
    self.stream.flush()
RuntimeError: reentrant call inside <_io.BufferedWriter name='/home/ubuntu/HeatExchanger_Only_IOT/gunicorn_error.log'>

During handling of the above exception, another exception occurred:

Traceback (most recent call last):
  File "/usr/lib/python3.12/logging/__init__.py", line 1164, in emit
    self.flush()
  File "/usr/lib/python3.12/logging/__init__.py", line 1144, in flush
    self.stream.flush()
RuntimeError: reentrant call inside <_io.BufferedWriter name='/home/ubuntu/HeatExchanger_Only_IOT/gunicorn_error.log'>
Call stack:
  File "/home/ubuntu/HeatExchanger_Only_IOT/venv/bin/gunicorn", line 8, in <module>
    sys.exit(run())
  File "/home/ubuntu/HeatExchanger_Only_IOT/venv/lib/python3.12/site-packages/gunicorn/app/wsgiapp.py", line 67, in run
    WSGIApplication("%(prog)s [OPTIONS] [APP_MODULE]").run()
  File "/home/ubuntu/HeatExchanger_Only_IOT/venv/lib/python3.12/site-packages/gunicorn/app/base.py", line 236, in run
    super().run()
  File "/home/ubuntu/HeatExchanger_Only_IOT/venv/lib/python3.12/site-packages/gunicorn/app/base.py", line 72, in run
    Arbiter(self).run()
  File "/home/ubuntu/HeatExchanger_Only_IOT/venv/lib/python3.12/site-packages/gunicorn/arbiter.py", line 223, in run
    self.log.info("Handling signal: %s", signame)
  File "/home/ubuntu/HeatExchanger_Only_IOT/venv/lib/python3.12/site-packages/gunicorn/glogging.py", line 278, in info
    self.error_log.info(msg, *args, **kwargs)
  File "/usr/lib/python3.12/logging/__init__.py", line 1539, in info
    self._log(INFO, msg, args, **kwargs)
  File "/usr/lib/python3.12/logging/__init__.py", line 1684, in _log
    self.handle(record)
  File "/usr/lib/python3.12/logging/__init__.py", line 1700, in handle
    self.callHandlers(record)
  File "/usr/lib/python3.12/logging/__init__.py", line 1762, in callHandlers
    hdlr.handle(record)
  File "/usr/lib/python3.12/logging/__init__.py", line 1028, in handle
    self.emit(record)
  File "/usr/lib/python3.12/logging/__init__.py", line 1280, in emit
    StreamHandler.emit(self, record)
  File "/usr/lib/python3.12/logging/__init__.py", line 1164, in emit
    self.flush()
  File "/usr/lib/python3.12/logging/__init__.py", line 1144, in flush
    self.stream.flush()
  File "/home/ubuntu/HeatExchanger_Only_IOT/venv/lib/python3.12/site-packages/gunicorn/arbiter.py", line 242, in handle_chld
    self.reap_workers()
  File "/home/ubuntu/HeatExchanger_Only_IOT/venv/lib/python3.12/site-packages/gunicorn/arbiter.py", line 554, in reap_workers
    self.log.error(msg)
  File "/home/ubuntu/HeatExchanger_Only_IOT/venv/lib/python3.12/site-packages/gunicorn/glogging.py", line 272, in error
    self.error_log.error(msg, *args, **kwargs)
  File "/usr/lib/python3.12/logging/__init__.py", line 1568, in error
    self._log(ERROR, msg, args, **kwargs)
  File "/usr/lib/python3.12/logging/__init__.py", line 1684, in _log
    self.handle(record)
  File "/usr/lib/python3.12/logging/__init__.py", line 1700, in handle
    self.callHandlers(record)
  File "/usr/lib/python3.12/logging/__init__.py", line 1762, in callHandlers
    hdlr.handle(record)
  File "/usr/lib/python3.12/logging/__init__.py", line 1028, in handle
    self.emit(record)
  File "/usr/lib/python3.12/logging/__init__.py", line 1280, in emit
    StreamHandler.emit(self, record)
  File "/usr/lib/python3.12/logging/__init__.py", line 1168, in emit
    self.handleError(record)
  File "/usr/lib/python3.12/logging/__init__.py", line 1082, in handleError
    traceback.print_exception(t, v, tb, None, sys.stderr)
  File "/usr/lib/python3.12/traceback.py", line 124, in print_exception
    te = TracebackException(type(value), value, tb, limit=limit, compact=True)
  File "/usr/lib/python3.12/traceback.py", line 733, in __init__
    self.stack = StackSummary._extract_from_extended_frame_gen(
  File "/usr/lib/python3.12/traceback.py", line 424, in _extract_from_extended_frame_gen
    linecache.lazycache(filename, f.f_globals)
  File "/usr/lib/python3.12/linecache.py", line 165, in lazycache
    if not filename or (filename.startswith('<') and filename.endswith('>')):
  File "/home/ubuntu/HeatExchanger_Only_IOT/venv/lib/python3.12/site-packages/gunicorn/arbiter.py", line 242, in handle_chld
    self.reap_workers()
  File "/home/ubuntu/HeatExchanger_Only_IOT/venv/lib/python3.12/site-packages/gunicorn/arbiter.py", line 554, in reap_workers
    self.log.error(msg)
  File "/home/ubuntu/HeatExchanger_Only_IOT/venv/lib/python3.12/site-packages/gunicorn/glogging.py", line 272, in error
    self.error_log.error(msg, *args, **kwargs)
Message: 'Worker (pid:8546) was sent SIGHUP!'
Arguments: ()
Traceback (most recent call last):
  File "/usr/lib/python3.12/logging/__init__.py", line 1164, in emit
    self.flush()
  File "/usr/lib/python3.12/logging/__init__.py", line 1144, in flush
    self.stream.flush()
RuntimeError: reentrant call inside <_io.BufferedWriter name='/home/ubuntu/HeatExchanger_Only_IOT/gunicorn_error.log'>
Call stack:
  File "/home/ubuntu/HeatExchanger_Only_IOT/venv/bin/gunicorn", line 8, in <module>
    sys.exit(run())
  File "/home/ubuntu/HeatExchanger_Only_IOT/venv/lib/python3.12/site-packages/gunicorn/app/wsgiapp.py", line 67, in run
    WSGIApplication("%(prog)s [OPTIONS] [APP_MODULE]").run()
  File "/home/ubuntu/HeatExchanger_Only_IOT/venv/lib/python3.12/site-packages/gunicorn/app/base.py", line 236, in run
    super().run()
  File "/home/ubuntu/HeatExchanger_Only_IOT/venv/lib/python3.12/site-packages/gunicorn/app/base.py", line 72, in run
    Arbiter(self).run()
  File "/home/ubuntu/HeatExchanger_Only_IOT/venv/lib/python3.12/site-packages/gunicorn/arbiter.py", line 223, in run
    self.log.info("Handling signal: %s", signame)
  File "/home/ubuntu/HeatExchanger_Only_IOT/venv/lib/python3.12/site-packages/gunicorn/glogging.py", line 278, in info
    self.error_log.info(msg, *args, **kwargs)
  File "/usr/lib/python3.12/logging/__init__.py", line 1539, in info
    self._log(INFO, msg, args, **kwargs)
  File "/usr/lib/python3.12/logging/__init__.py", line 1684, in _log
    self.handle(record)
  File "/usr/lib/python3.12/logging/__init__.py", line 1700, in handle
    self.callHandlers(record)
  File "/usr/lib/python3.12/logging/__init__.py", line 1762, in callHandlers
    hdlr.handle(record)
  File "/usr/lib/python3.12/logging/__init__.py", line 1028, in handle
    self.emit(record)
  File "/usr/lib/python3.12/logging/__init__.py", line 1280, in emit
    StreamHandler.emit(self, record)
  File "/usr/lib/python3.12/logging/__init__.py", line 1164, in emit
    self.flush()
  File "/usr/lib/python3.12/logging/__init__.py", line 1144, in flush
    self.stream.flush()
  File "/home/ubuntu/HeatExchanger_Only_IOT/venv/lib/python3.12/site-packages/gunicorn/arbiter.py", line 242, in handle_chld
    self.reap_workers()
  File "/home/ubuntu/HeatExchanger_Only_IOT/venv/lib/python3.12/site-packages/gunicorn/arbiter.py", line 554, in reap_workers
    self.log.error(msg)
  File "/home/ubuntu/HeatExchanger_Only_IOT/venv/lib/python3.12/site-packages/gunicorn/glogging.py", line 272, in error
    self.error_log.error(msg, *args, **kwargs)
Message: 'Worker (pid:8547) was sent SIGHUP!'
Arguments: ()
