Watching for file changes with StatReloader
Not Found: /api
[15/Sep/2025 09:22:46] "GET /api HTTP/1.1" 404 2337
Internal Server Error: /admin/api/apikey/
Traceback (most recent call last):
  File "/Users/sameerwadekar/miniconda3/envs/tf-mac/lib/python3.10/site-packages/django/db/backends/utils.py", line 105, in _execute
    return self.cursor.execute(sql, params)
  File "/Users/sameerwadekar/miniconda3/envs/tf-mac/lib/python3.10/site-packages/django/db/backends/sqlite3/base.py", line 354, in execute
    return super().execute(query, params)
sqlite3.OperationalError: no such column: api_apikey.created_at

The above exception was the direct cause of the following exception:

Traceback (most recent call last):
  File "/Users/sameerwadekar/miniconda3/envs/tf-mac/lib/python3.10/site-packages/django/core/handlers/exception.py", line 55, in inner
    response = get_response(request)
  File "/Users/sameerwadekar/miniconda3/envs/tf-mac/lib/python3.10/site-packages/django/core/handlers/base.py", line 197, in _get_response
    response = wrapped_callback(request, *callback_args, **callback_kwargs)
  File "/Users/sameerwadekar/miniconda3/envs/tf-mac/lib/python3.10/site-packages/django/contrib/admin/options.py", line 718, in wrapper
    return self.admin_site.admin_view(view)(*args, **kwargs)
  File "/Users/sameerwadekar/miniconda3/envs/tf-mac/lib/python3.10/site-packages/django/utils/decorators.py", line 188, in _view_wrapper
    result = _process_exception(request, e)
  File "/Users/sameerwadekar/miniconda3/envs/tf-mac/lib/python3.10/site-packages/django/utils/decorators.py", line 186, in _view_wrapper
    response = view_func(request, *args, **kwargs)
  File "/Users/sameerwadekar/miniconda3/envs/tf-mac/lib/python3.10/site-packages/django/views/decorators/cache.py", line 80, in _view_wrapper
    response = view_func(request, *args, **kwargs)
  File "/Users/sameerwadekar/miniconda3/envs/tf-mac/lib/python3.10/site-packages/django/contrib/admin/sites.py", line 241, in inner
    return view(request, *args, **kwargs)
  File "/Users/sameerwadekar/miniconda3/envs/tf-mac/lib/python3.10/site-packages/django/utils/decorators.py", line 48, in _wrapper
    return bound_method(*args, **kwargs)
  File "/Users/sameerwadekar/miniconda3/envs/tf-mac/lib/python3.10/site-packages/django/utils/decorators.py", line 188, in _view_wrapper
    result = _process_exception(request, e)
  File "/Users/sameerwadekar/miniconda3/envs/tf-mac/lib/python3.10/site-packages/django/utils/decorators.py", line 186, in _view_wrapper
    response = view_func(request, *args, **kwargs)
  File "/Users/sameerwadekar/miniconda3/envs/tf-mac/lib/python3.10/site-packages/django/contrib/admin/options.py", line 2140, in changelist_view
    "selection_note": _("0 of %(cnt)s selected") % {"cnt": len(cl.result_list)},
  File "/Users/sameerwadekar/miniconda3/envs/tf-mac/lib/python3.10/site-packages/django/db/models/query.py", line 382, in __len__
    self._fetch_all()
  File "/Users/sameerwadekar/miniconda3/envs/tf-mac/lib/python3.10/site-packages/django/db/models/query.py", line 1928, in _fetch_all
    self._result_cache = list(self._iterable_class(self))
  File "/Users/sameerwadekar/miniconda3/envs/tf-mac/lib/python3.10/site-packages/django/db/models/query.py", line 91, in __iter__
    results = compiler.execute_sql(
  File "/Users/sameerwadekar/miniconda3/envs/tf-mac/lib/python3.10/site-packages/django/db/models/sql/compiler.py", line 1574, in execute_sql
    cursor.execute(sql, params)
  File "/Users/sameerwadekar/miniconda3/envs/tf-mac/lib/python3.10/site-packages/django/db/backends/utils.py", line 122, in execute
    return super().execute(sql, params)
  File "/Users/sameerwadekar/miniconda3/envs/tf-mac/lib/python3.10/site-packages/django/db/backends/utils.py", line 79, in execute
    return self._execute_with_wrappers(
  File "/Users/sameerwadekar/miniconda3/envs/tf-mac/lib/python3.10/site-packages/django/db/backends/utils.py", line 92, in _execute_with_wrappers
    return executor(sql, params, many, context)
  File "/Users/sameerwadekar/miniconda3/envs/tf-mac/lib/python3.10/site-packages/django/db/backends/utils.py", line 100, in _execute
    with self.db.wrap_database_errors:
  File "/Users/sameerwadekar/miniconda3/envs/tf-mac/lib/python3.10/site-packages/django/db/utils.py", line 91, in __exit__
    raise dj_exc_value.with_traceback(traceback) from exc_value
  File "/Users/sameerwadekar/miniconda3/envs/tf-mac/lib/python3.10/site-packages/django/db/backends/utils.py", line 105, in _execute
    return self.cursor.execute(sql, params)
  File "/Users/sameerwadekar/miniconda3/envs/tf-mac/lib/python3.10/site-packages/django/db/backends/sqlite3/base.py", line 354, in execute
    return super().execute(query, params)
django.db.utils.OperationalError: no such column: api_apikey.created_at
[15/Sep/2025 09:22:49] "GET /admin/api/apikey/ HTTP/1.1" 500 167195
Not Found: /
[15/Sep/2025 09:22:50] "GET / HTTP/1.1" 404 2310
[15/Sep/2025 09:22:51] "GET /admin/ HTTP/1.1" 200 7605
[15/Sep/2025 09:22:51] "GET /static/admin/css/base.css HTTP/1.1" 304 0
[15/Sep/2025 09:22:51] "GET /static/admin/js/theme.js HTTP/1.1" 304 0
[15/Sep/2025 09:22:51] "GET /static/admin/css/responsive.css HTTP/1.1" 304 0
[15/Sep/2025 09:22:51] "GET /static/admin/css/dark_mode.css HTTP/1.1" 304 0
[15/Sep/2025 09:22:51] "GET /static/admin/css/nav_sidebar.css HTTP/1.1" 304 0
[15/Sep/2025 09:22:51] "GET /static/admin/js/nav_sidebar.js HTTP/1.1" 304 0
[15/Sep/2025 09:22:51] "GET /static/admin/css/dashboard.css HTTP/1.1" 304 0
[15/Sep/2025 09:22:51] "GET /static/admin/img/icon-changelink.svg HTTP/1.1" 304 0
[15/Sep/2025 09:22:51] "GET /static/admin/img/icon-addlink.svg HTTP/1.1" 304 0
Internal Server Error: /admin/api/customer/1/change/
Traceback (most recent call last):
  File "/Users/sameerwadekar/miniconda3/envs/tf-mac/lib/python3.10/site-packages/django/db/backends/utils.py", line 105, in _execute
    return self.cursor.execute(sql, params)
  File "/Users/sameerwadekar/miniconda3/envs/tf-mac/lib/python3.10/site-packages/django/db/backends/sqlite3/base.py", line 354, in execute
    return super().execute(query, params)
sqlite3.OperationalError: no such column: api_customer.email

The above exception was the direct cause of the following exception:

Traceback (most recent call last):
  File "/Users/sameerwadekar/miniconda3/envs/tf-mac/lib/python3.10/site-packages/django/core/handlers/exception.py", line 55, in inner
    response = get_response(request)
  File "/Users/sameerwadekar/miniconda3/envs/tf-mac/lib/python3.10/site-packages/django/core/handlers/base.py", line 197, in _get_response
    response = wrapped_callback(request, *callback_args, **callback_kwargs)
  File "/Users/sameerwadekar/miniconda3/envs/tf-mac/lib/python3.10/site-packages/django/contrib/admin/options.py", line 718, in wrapper
    return self.admin_site.admin_view(view)(*args, **kwargs)
  File "/Users/sameerwadekar/miniconda3/envs/tf-mac/lib/python3.10/site-packages/django/utils/decorators.py", line 188, in _view_wrapper
    result = _process_exception(request, e)
  File "/Users/sameerwadekar/miniconda3/envs/tf-mac/lib/python3.10/site-packages/django/utils/decorators.py", line 186, in _view_wrapper
    response = view_func(request, *args, **kwargs)
  File "/Users/sameerwadekar/miniconda3/envs/tf-mac/lib/python3.10/site-packages/django/views/decorators/cache.py", line 80, in _view_wrapper
    response = view_func(request, *args, **kwargs)
  File "/Users/sameerwadekar/miniconda3/envs/tf-mac/lib/python3.10/site-packages/django/contrib/admin/sites.py", line 241, in inner
    return view(request, *args, **kwargs)
  File "/Users/sameerwadekar/miniconda3/envs/tf-mac/lib/python3.10/site-packages/django/contrib/admin/options.py", line 1964, in change_view
    return self.changeform_view(request, object_id, form_url, extra_context)
  File "/Users/sameerwadekar/miniconda3/envs/tf-mac/lib/python3.10/site-packages/django/utils/decorators.py", line 48, in _wrapper
    return bound_method(*args, **kwargs)
  File "/Users/sameerwadekar/miniconda3/envs/tf-mac/lib/python3.10/site-packages/django/utils/decorators.py", line 188, in _view_wrapper
    result = _process_exception(request, e)
  File "/Users/sameerwadekar/miniconda3/envs/tf-mac/lib/python3.10/site-packages/django/utils/decorators.py", line 186, in _view_wrapper
    response = view_func(request, *args, **kwargs)
  File "/Users/sameerwadekar/miniconda3/envs/tf-mac/lib/python3.10/site-packages/django/contrib/admin/options.py", line 1820, in changeform_view
    return self._changeform_view(request, object_id, form_url, extra_context)
  File "/Users/sameerwadekar/miniconda3/envs/tf-mac/lib/python3.10/site-packages/django/contrib/admin/options.py", line 1840, in _changeform_view
    obj = self.get_object(request, unquote(object_id), to_field)
  File "/Users/sameerwadekar/miniconda3/envs/tf-mac/lib/python3.10/site-packages/django/contrib/admin/options.py", line 896, in get_object
    return queryset.get(**{field.name: object_id})
  File "/Users/sameerwadekar/miniconda3/envs/tf-mac/lib/python3.10/site-packages/django/db/models/query.py", line 645, in get
    num = len(clone)
  File "/Users/sameerwadekar/miniconda3/envs/tf-mac/lib/python3.10/site-packages/django/db/models/query.py", line 382, in __len__
    self._fetch_all()
  File "/Users/sameerwadekar/miniconda3/envs/tf-mac/lib/python3.10/site-packages/django/db/models/query.py", line 1928, in _fetch_all
    self._result_cache = list(self._iterable_class(self))
  File "/Users/sameerwadekar/miniconda3/envs/tf-mac/lib/python3.10/site-packages/django/db/models/query.py", line 91, in __iter__
    results = compiler.execute_sql(
  File "/Users/sameerwadekar/miniconda3/envs/tf-mac/lib/python3.10/site-packages/django/db/models/sql/compiler.py", line 1574, in execute_sql
    cursor.execute(sql, params)
  File "/Users/sameerwadekar/miniconda3/envs/tf-mac/lib/python3.10/site-packages/django/db/backends/utils.py", line 122, in execute
    return super().execute(sql, params)
  File "/Users/sameerwadekar/miniconda3/envs/tf-mac/lib/python3.10/site-packages/django/db/backends/utils.py", line 79, in execute
    return self._execute_with_wrappers(
  File "/Users/sameerwadekar/miniconda3/envs/tf-mac/lib/python3.10/site-packages/django/db/backends/utils.py", line 92, in _execute_with_wrappers
    return executor(sql, params, many, context)
  File "/Users/sameerwadekar/miniconda3/envs/tf-mac/lib/python3.10/site-packages/django/db/backends/utils.py", line 100, in _execute
    with self.db.wrap_database_errors:
  File "/Users/sameerwadekar/miniconda3/envs/tf-mac/lib/python3.10/site-packages/django/db/utils.py", line 91, in __exit__
    raise dj_exc_value.with_traceback(traceback) from exc_value
  File "/Users/sameerwadekar/miniconda3/envs/tf-mac/lib/python3.10/site-packages/django/db/backends/utils.py", line 105, in _execute
    return self.cursor.execute(sql, params)
  File "/Users/sameerwadekar/miniconda3/envs/tf-mac/lib/python3.10/site-packages/django/db/backends/sqlite3/base.py", line 354, in execute
    return super().execute(query, params)
django.db.utils.OperationalError: no such column: api_customer.email
[15/Sep/2025 09:22:56] "GET /admin/api/customer/1/change/ HTTP/1.1" 500 181323
Internal Server Error: /admin/api/customer/1/change/
Traceback (most recent call last):
  File "/Users/sameerwadekar/miniconda3/envs/tf-mac/lib/python3.10/site-packages/django/db/backends/utils.py", line 105, in _execute
    return self.cursor.execute(sql, params)
  File "/Users/sameerwadekar/miniconda3/envs/tf-mac/lib/python3.10/site-packages/django/db/backends/sqlite3/base.py", line 354, in execute
    return super().execute(query, params)
sqlite3.OperationalError: no such column: api_customer.email

The above exception was the direct cause of the following exception:

Traceback (most recent call last):
  File "/Users/sameerwadekar/miniconda3/envs/tf-mac/lib/python3.10/site-packages/django/core/handlers/exception.py", line 55, in inner
    response = get_response(request)
  File "/Users/sameerwadekar/miniconda3/envs/tf-mac/lib/python3.10/site-packages/django/core/handlers/base.py", line 197, in _get_response
    response = wrapped_callback(request, *callback_args, **callback_kwargs)
  File "/Users/sameerwadekar/miniconda3/envs/tf-mac/lib/python3.10/site-packages/django/contrib/admin/options.py", line 718, in wrapper
    return self.admin_site.admin_view(view)(*args, **kwargs)
  File "/Users/sameerwadekar/miniconda3/envs/tf-mac/lib/python3.10/site-packages/django/utils/decorators.py", line 188, in _view_wrapper
    result = _process_exception(request, e)
  File "/Users/sameerwadekar/miniconda3/envs/tf-mac/lib/python3.10/site-packages/django/utils/decorators.py", line 186, in _view_wrapper
    response = view_func(request, *args, **kwargs)
  File "/Users/sameerwadekar/miniconda3/envs/tf-mac/lib/python3.10/site-packages/django/views/decorators/cache.py", line 80, in _view_wrapper
    response = view_func(request, *args, **kwargs)
  File "/Users/sameerwadekar/miniconda3/envs/tf-mac/lib/python3.10/site-packages/django/contrib/admin/sites.py", line 241, in inner
    return view(request, *args, **kwargs)
  File "/Users/sameerwadekar/miniconda3/envs/tf-mac/lib/python3.10/site-packages/django/contrib/admin/options.py", line 1964, in change_view
    return self.changeform_view(request, object_id, form_url, extra_context)
  File "/Users/sameerwadekar/miniconda3/envs/tf-mac/lib/python3.10/site-packages/django/utils/decorators.py", line 48, in _wrapper
    return bound_method(*args, **kwargs)
  File "/Users/sameerwadekar/miniconda3/envs/tf-mac/lib/python3.10/site-packages/django/utils/decorators.py", line 188, in _view_wrapper
    result = _process_exception(request, e)
  File "/Users/sameerwadekar/miniconda3/envs/tf-mac/lib/python3.10/site-packages/django/utils/decorators.py", line 186, in _view_wrapper
    response = view_func(request, *args, **kwargs)
  File "/Users/sameerwadekar/miniconda3/envs/tf-mac/lib/python3.10/site-packages/django/contrib/admin/options.py", line 1820, in changeform_view
    return self._changeform_view(request, object_id, form_url, extra_context)
  File "/Users/sameerwadekar/miniconda3/envs/tf-mac/lib/python3.10/site-packages/django/contrib/admin/options.py", line 1840, in _changeform_view
    obj = self.get_object(request, unquote(object_id), to_field)
  File "/Users/sameerwadekar/miniconda3/envs/tf-mac/lib/python3.10/site-packages/django/contrib/admin/options.py", line 896, in get_object
    return queryset.get(**{field.name: object_id})
  File "/Users/sameerwadekar/miniconda3/envs/tf-mac/lib/python3.10/site-packages/django/db/models/query.py", line 645, in get
    num = len(clone)
  File "/Users/sameerwadekar/miniconda3/envs/tf-mac/lib/python3.10/site-packages/django/db/models/query.py", line 382, in __len__
    self._fetch_all()
  File "/Users/sameerwadekar/miniconda3/envs/tf-mac/lib/python3.10/site-packages/django/db/models/query.py", line 1928, in _fetch_all
    self._result_cache = list(self._iterable_class(self))
  File "/Users/sameerwadekar/miniconda3/envs/tf-mac/lib/python3.10/site-packages/django/db/models/query.py", line 91, in __iter__
    results = compiler.execute_sql(
  File "/Users/sameerwadekar/miniconda3/envs/tf-mac/lib/python3.10/site-packages/django/db/models/sql/compiler.py", line 1574, in execute_sql
    cursor.execute(sql, params)
  File "/Users/sameerwadekar/miniconda3/envs/tf-mac/lib/python3.10/site-packages/django/db/backends/utils.py", line 122, in execute
    return super().execute(sql, params)
  File "/Users/sameerwadekar/miniconda3/envs/tf-mac/lib/python3.10/site-packages/django/db/backends/utils.py", line 79, in execute
    return self._execute_with_wrappers(
  File "/Users/sameerwadekar/miniconda3/envs/tf-mac/lib/python3.10/site-packages/django/db/backends/utils.py", line 92, in _execute_with_wrappers
    return executor(sql, params, many, context)
  File "/Users/sameerwadekar/miniconda3/envs/tf-mac/lib/python3.10/site-packages/django/db/backends/utils.py", line 100, in _execute
    with self.db.wrap_database_errors:
  File "/Users/sameerwadekar/miniconda3/envs/tf-mac/lib/python3.10/site-packages/django/db/utils.py", line 91, in __exit__
    raise dj_exc_value.with_traceback(traceback) from exc_value
  File "/Users/sameerwadekar/miniconda3/envs/tf-mac/lib/python3.10/site-packages/django/db/backends/utils.py", line 105, in _execute
    return self.cursor.execute(sql, params)
  File "/Users/sameerwadekar/miniconda3/envs/tf-mac/lib/python3.10/site-packages/django/db/backends/sqlite3/base.py", line 354, in execute
    return super().execute(query, params)
django.db.utils.OperationalError: no such column: api_customer.email
[15/Sep/2025 09:23:10] "GET /admin/api/customer/1/change/ HTTP/1.1" 500 181166
Internal Server Error: /admin/api/apikey/
Traceback (most recent call last):
  File "/Users/sameerwadekar/miniconda3/envs/tf-mac/lib/python3.10/site-packages/django/db/backends/utils.py", line 105, in _execute
    return self.cursor.execute(sql, params)
  File "/Users/sameerwadekar/miniconda3/envs/tf-mac/lib/python3.10/site-packages/django/db/backends/sqlite3/base.py", line 354, in execute
    return super().execute(query, params)
sqlite3.OperationalError: no such column: api_apikey.created_at

The above exception was the direct cause of the following exception:

Traceback (most recent call last):
  File "/Users/sameerwadekar/miniconda3/envs/tf-mac/lib/python3.10/site-packages/django/core/handlers/exception.py", line 55, in inner
    response = get_response(request)
  File "/Users/sameerwadekar/miniconda3/envs/tf-mac/lib/python3.10/site-packages/django/core/handlers/base.py", line 197, in _get_response
    response = wrapped_callback(request, *callback_args, **callback_kwargs)
  File "/Users/sameerwadekar/miniconda3/envs/tf-mac/lib/python3.10/site-packages/django/contrib/admin/options.py", line 718, in wrapper
    return self.admin_site.admin_view(view)(*args, **kwargs)
  File "/Users/sameerwadekar/miniconda3/envs/tf-mac/lib/python3.10/site-packages/django/utils/decorators.py", line 188, in _view_wrapper
    result = _process_exception(request, e)
  File "/Users/sameerwadekar/miniconda3/envs/tf-mac/lib/python3.10/site-packages/django/utils/decorators.py", line 186, in _view_wrapper
    response = view_func(request, *args, **kwargs)
  File "/Users/sameerwadekar/miniconda3/envs/tf-mac/lib/python3.10/site-packages/django/views/decorators/cache.py", line 80, in _view_wrapper
    response = view_func(request, *args, **kwargs)
  File "/Users/sameerwadekar/miniconda3/envs/tf-mac/lib/python3.10/site-packages/django/contrib/admin/sites.py", line 241, in inner
    return view(request, *args, **kwargs)
  File "/Users/sameerwadekar/miniconda3/envs/tf-mac/lib/python3.10/site-packages/django/utils/decorators.py", line 48, in _wrapper
    return bound_method(*args, **kwargs)
  File "/Users/sameerwadekar/miniconda3/envs/tf-mac/lib/python3.10/site-packages/django/utils/decorators.py", line 188, in _view_wrapper
    result = _process_exception(request, e)
  File "/Users/sameerwadekar/miniconda3/envs/tf-mac/lib/python3.10/site-packages/django/utils/decorators.py", line 186, in _view_wrapper
    response = view_func(request, *args, **kwargs)
  File "/Users/sameerwadekar/miniconda3/envs/tf-mac/lib/python3.10/site-packages/django/contrib/admin/options.py", line 2140, in changelist_view
    "selection_note": _("0 of %(cnt)s selected") % {"cnt": len(cl.result_list)},
  File "/Users/sameerwadekar/miniconda3/envs/tf-mac/lib/python3.10/site-packages/django/db/models/query.py", line 382, in __len__
    self._fetch_all()
  File "/Users/sameerwadekar/miniconda3/envs/tf-mac/lib/python3.10/site-packages/django/db/models/query.py", line 1928, in _fetch_all
    self._result_cache = list(self._iterable_class(self))
  File "/Users/sameerwadekar/miniconda3/envs/tf-mac/lib/python3.10/site-packages/django/db/models/query.py", line 91, in __iter__
    results = compiler.execute_sql(
  File "/Users/sameerwadekar/miniconda3/envs/tf-mac/lib/python3.10/site-packages/django/db/models/sql/compiler.py", line 1574, in execute_sql
    cursor.execute(sql, params)
  File "/Users/sameerwadekar/miniconda3/envs/tf-mac/lib/python3.10/site-packages/django/db/backends/utils.py", line 122, in execute
    return super().execute(sql, params)
  File "/Users/sameerwadekar/miniconda3/envs/tf-mac/lib/python3.10/site-packages/django/db/backends/utils.py", line 79, in execute
    return self._execute_with_wrappers(
  File "/Users/sameerwadekar/miniconda3/envs/tf-mac/lib/python3.10/site-packages/django/db/backends/utils.py", line 92, in _execute_with_wrappers
    return executor(sql, params, many, context)
  File "/Users/sameerwadekar/miniconda3/envs/tf-mac/lib/python3.10/site-packages/django/db/backends/utils.py", line 100, in _execute
    with self.db.wrap_database_errors:
  File "/Users/sameerwadekar/miniconda3/envs/tf-mac/lib/python3.10/site-packages/django/db/utils.py", line 91, in __exit__
    raise dj_exc_value.with_traceback(traceback) from exc_value
  File "/Users/sameerwadekar/miniconda3/envs/tf-mac/lib/python3.10/site-packages/django/db/backends/utils.py", line 105, in _execute
    return self.cursor.execute(sql, params)
  File "/Users/sameerwadekar/miniconda3/envs/tf-mac/lib/python3.10/site-packages/django/db/backends/sqlite3/base.py", line 354, in execute
    return super().execute(query, params)
django.db.utils.OperationalError: no such column: api_apikey.created_at
[15/Sep/2025 09:23:12] "GET /admin/api/apikey/ HTTP/1.1" 500 167195
[15/Sep/2025 09:23:13] "GET /admin/ HTTP/1.1" 200 7605
[15/Sep/2025 09:23:16] "GET /admin/api/customer/add/ HTTP/1.1" 200 9560
[15/Sep/2025 09:23:16] "GET /static/admin/css/forms.css HTTP/1.1" 304 0
[15/Sep/2025 09:23:16] "GET /static/admin/js/jquery.init.js HTTP/1.1" 304 0
[15/Sep/2025 09:23:16] "GET /static/admin/js/admin/RelatedObjectLookups.js HTTP/1.1" 304 0
[15/Sep/2025 09:23:16] "GET /static/admin/js/core.js HTTP/1.1" 304 0
[15/Sep/2025 09:23:16] "GET /static/admin/js/actions.js HTTP/1.1" 304 0
[15/Sep/2025 09:23:16] "GET /static/admin/js/prepopulate.js HTTP/1.1" 304 0
[15/Sep/2025 09:23:16] "GET /static/admin/js/vendor/jquery/jquery.js HTTP/1.1" 304 0
[15/Sep/2025 09:23:16] "GET /static/admin/js/urlify.js HTTP/1.1" 304 0
[15/Sep/2025 09:23:16] "GET /static/admin/js/prepopulate_init.js HTTP/1.1" 304 0
[15/Sep/2025 09:23:16] "GET /static/admin/js/change_form.js HTTP/1.1" 304 0
[15/Sep/2025 09:23:16] "GET /static/admin/js/vendor/xregexp/xregexp.js HTTP/1.1" 304 0
[15/Sep/2025 09:23:16] "GET /static/admin/css/widgets.css HTTP/1.1" 304 0
[15/Sep/2025 09:23:16] "GET /admin/jsi18n/ HTTP/1.1" 200 3342
Internal Server Error: /admin/api/customer/add/
Traceback (most recent call last):
  File "/Users/sameerwadekar/miniconda3/envs/tf-mac/lib/python3.10/site-packages/django/db/backends/utils.py", line 105, in _execute
    return self.cursor.execute(sql, params)
  File "/Users/sameerwadekar/miniconda3/envs/tf-mac/lib/python3.10/site-packages/django/db/backends/sqlite3/base.py", line 354, in execute
    return super().execute(query, params)
sqlite3.OperationalError: table api_customer has no column named email

The above exception was the direct cause of the following exception:

Traceback (most recent call last):
  File "/Users/sameerwadekar/miniconda3/envs/tf-mac/lib/python3.10/site-packages/django/core/handlers/exception.py", line 55, in inner
    response = get_response(request)
  File "/Users/sameerwadekar/miniconda3/envs/tf-mac/lib/python3.10/site-packages/django/core/handlers/base.py", line 197, in _get_response
    response = wrapped_callback(request, *callback_args, **callback_kwargs)
  File "/Users/sameerwadekar/miniconda3/envs/tf-mac/lib/python3.10/site-packages/django/contrib/admin/options.py", line 718, in wrapper
    return self.admin_site.admin_view(view)(*args, **kwargs)
  File "/Users/sameerwadekar/miniconda3/envs/tf-mac/lib/python3.10/site-packages/django/utils/decorators.py", line 188, in _view_wrapper
    result = _process_exception(request, e)
  File "/Users/sameerwadekar/miniconda3/envs/tf-mac/lib/python3.10/site-packages/django/utils/decorators.py", line 186, in _view_wrapper
    response = view_func(request, *args, **kwargs)
  File "/Users/sameerwadekar/miniconda3/envs/tf-mac/lib/python3.10/site-packages/django/views/decorators/cache.py", line 80, in _view_wrapper
    response = view_func(request, *args, **kwargs)
  File "/Users/sameerwadekar/miniconda3/envs/tf-mac/lib/python3.10/site-packages/django/contrib/admin/sites.py", line 241, in inner
    return view(request, *args, **kwargs)
  File "/Users/sameerwadekar/miniconda3/envs/tf-mac/lib/python3.10/site-packages/django/contrib/admin/options.py", line 1961, in add_view
    return self.changeform_view(request, None, form_url, extra_context)
  File "/Users/sameerwadekar/miniconda3/envs/tf-mac/lib/python3.10/site-packages/django/utils/decorators.py", line 48, in _wrapper
    return bound_method(*args, **kwargs)
  File "/Users/sameerwadekar/miniconda3/envs/tf-mac/lib/python3.10/site-packages/django/utils/decorators.py", line 188, in _view_wrapper
    result = _process_exception(request, e)
  File "/Users/sameerwadekar/miniconda3/envs/tf-mac/lib/python3.10/site-packages/django/utils/decorators.py", line 186, in _view_wrapper
    response = view_func(request, *args, **kwargs)
  File "/Users/sameerwadekar/miniconda3/envs/tf-mac/lib/python3.10/site-packages/django/contrib/admin/options.py", line 1820, in changeform_view
    return self._changeform_view(request, object_id, form_url, extra_context)
  File "/Users/sameerwadekar/miniconda3/envs/tf-mac/lib/python3.10/site-packages/django/contrib/admin/options.py", line 1871, in _changeform_view
    self.save_model(request, new_object, form, not add)
  File "/Users/sameerwadekar/miniconda3/envs/tf-mac/lib/python3.10/site-packages/django/contrib/admin/options.py", line 1294, in save_model
    obj.save()
  File "/Users/sameerwadekar/miniconda3/envs/tf-mac/lib/python3.10/site-packages/django/db/models/base.py", line 891, in save
    self.save_base(
  File "/Users/sameerwadekar/miniconda3/envs/tf-mac/lib/python3.10/site-packages/django/db/models/base.py", line 997, in save_base
    updated = self._save_table(
  File "/Users/sameerwadekar/miniconda3/envs/tf-mac/lib/python3.10/site-packages/django/db/models/base.py", line 1160, in _save_table
    results = self._do_insert(
  File "/Users/sameerwadekar/miniconda3/envs/tf-mac/lib/python3.10/site-packages/django/db/models/base.py", line 1201, in _do_insert
    return manager._insert(
  File "/Users/sameerwadekar/miniconda3/envs/tf-mac/lib/python3.10/site-packages/django/db/models/manager.py", line 87, in manager_method
    return getattr(self.get_queryset(), name)(*args, **kwargs)
  File "/Users/sameerwadekar/miniconda3/envs/tf-mac/lib/python3.10/site-packages/django/db/models/query.py", line 1847, in _insert
    return query.get_compiler(using=using).execute_sql(returning_fields)
  File "/Users/sameerwadekar/miniconda3/envs/tf-mac/lib/python3.10/site-packages/django/db/models/sql/compiler.py", line 1836, in execute_sql
    cursor.execute(sql, params)
  File "/Users/sameerwadekar/miniconda3/envs/tf-mac/lib/python3.10/site-packages/django/db/backends/utils.py", line 122, in execute
    return super().execute(sql, params)
  File "/Users/sameerwadekar/miniconda3/envs/tf-mac/lib/python3.10/site-packages/django/db/backends/utils.py", line 79, in execute
    return self._execute_with_wrappers(
  File "/Users/sameerwadekar/miniconda3/envs/tf-mac/lib/python3.10/site-packages/django/db/backends/utils.py", line 92, in _execute_with_wrappers
    return executor(sql, params, many, context)
  File "/Users/sameerwadekar/miniconda3/envs/tf-mac/lib/python3.10/site-packages/django/db/backends/utils.py", line 100, in _execute
    with self.db.wrap_database_errors:
  File "/Users/sameerwadekar/miniconda3/envs/tf-mac/lib/python3.10/site-packages/django/db/utils.py", line 91, in __exit__
    raise dj_exc_value.with_traceback(traceback) from exc_value
  File "/Users/sameerwadekar/miniconda3/envs/tf-mac/lib/python3.10/site-packages/django/db/backends/utils.py", line 105, in _execute
    return self.cursor.execute(sql, params)
  File "/Users/sameerwadekar/miniconda3/envs/tf-mac/lib/python3.10/site-packages/django/db/backends/sqlite3/base.py", line 354, in execute
    return super().execute(query, params)
django.db.utils.OperationalError: table api_customer has no column named email
[15/Sep/2025 09:23:38] "POST /admin/api/customer/add/ HTTP/1.1" 500 197488
[15/Sep/2025 09:24:01] "GET /admin/ HTTP/1.1" 200 7605
Internal Server Error: /admin/api/customer/1/change/
Traceback (most recent call last):
  File "/Users/sameerwadekar/miniconda3/envs/tf-mac/lib/python3.10/site-packages/django/db/backends/utils.py", line 105, in _execute
    return self.cursor.execute(sql, params)
  File "/Users/sameerwadekar/miniconda3/envs/tf-mac/lib/python3.10/site-packages/django/db/backends/sqlite3/base.py", line 354, in execute
    return super().execute(query, params)
sqlite3.OperationalError: no such column: api_customer.email

The above exception was the direct cause of the following exception:

Traceback (most recent call last):
  File "/Users/sameerwadekar/miniconda3/envs/tf-mac/lib/python3.10/site-packages/django/core/handlers/exception.py", line 55, in inner
    response = get_response(request)
  File "/Users/sameerwadekar/miniconda3/envs/tf-mac/lib/python3.10/site-packages/django/core/handlers/base.py", line 197, in _get_response
    response = wrapped_callback(request, *callback_args, **callback_kwargs)
  File "/Users/sameerwadekar/miniconda3/envs/tf-mac/lib/python3.10/site-packages/django/contrib/admin/options.py", line 718, in wrapper
    return self.admin_site.admin_view(view)(*args, **kwargs)
  File "/Users/sameerwadekar/miniconda3/envs/tf-mac/lib/python3.10/site-packages/django/utils/decorators.py", line 188, in _view_wrapper
    result = _process_exception(request, e)
  File "/Users/sameerwadekar/miniconda3/envs/tf-mac/lib/python3.10/site-packages/django/utils/decorators.py", line 186, in _view_wrapper
    response = view_func(request, *args, **kwargs)
  File "/Users/sameerwadekar/miniconda3/envs/tf-mac/lib/python3.10/site-packages/django/views/decorators/cache.py", line 80, in _view_wrapper
    response = view_func(request, *args, **kwargs)
  File "/Users/sameerwadekar/miniconda3/envs/tf-mac/lib/python3.10/site-packages/django/contrib/admin/sites.py", line 241, in inner
    return view(request, *args, **kwargs)
  File "/Users/sameerwadekar/miniconda3/envs/tf-mac/lib/python3.10/site-packages/django/contrib/admin/options.py", line 1964, in change_view
    return self.changeform_view(request, object_id, form_url, extra_context)
  File "/Users/sameerwadekar/miniconda3/envs/tf-mac/lib/python3.10/site-packages/django/utils/decorators.py", line 48, in _wrapper
    return bound_method(*args, **kwargs)
  File "/Users/sameerwadekar/miniconda3/envs/tf-mac/lib/python3.10/site-packages/django/utils/decorators.py", line 188, in _view_wrapper
    result = _process_exception(request, e)
  File "/Users/sameerwadekar/miniconda3/envs/tf-mac/lib/python3.10/site-packages/django/utils/decorators.py", line 186, in _view_wrapper
    response = view_func(request, *args, **kwargs)
  File "/Users/sameerwadekar/miniconda3/envs/tf-mac/lib/python3.10/site-packages/django/contrib/admin/options.py", line 1820, in changeform_view
    return self._changeform_view(request, object_id, form_url, extra_context)
  File "/Users/sameerwadekar/miniconda3/envs/tf-mac/lib/python3.10/site-packages/django/contrib/admin/options.py", line 1840, in _changeform_view
    obj = self.get_object(request, unquote(object_id), to_field)
  File "/Users/sameerwadekar/miniconda3/envs/tf-mac/lib/python3.10/site-packages/django/contrib/admin/options.py", line 896, in get_object
    return queryset.get(**{field.name: object_id})
  File "/Users/sameerwadekar/miniconda3/envs/tf-mac/lib/python3.10/site-packages/django/db/models/query.py", line 645, in get
    num = len(clone)
  File "/Users/sameerwadekar/miniconda3/envs/tf-mac/lib/python3.10/site-packages/django/db/models/query.py", line 382, in __len__
    self._fetch_all()
  File "/Users/sameerwadekar/miniconda3/envs/tf-mac/lib/python3.10/site-packages/django/db/models/query.py", line 1928, in _fetch_all
    self._result_cache = list(self._iterable_class(self))
  File "/Users/sameerwadekar/miniconda3/envs/tf-mac/lib/python3.10/site-packages/django/db/models/query.py", line 91, in __iter__
    results = compiler.execute_sql(
  File "/Users/sameerwadekar/miniconda3/envs/tf-mac/lib/python3.10/site-packages/django/db/models/sql/compiler.py", line 1574, in execute_sql
    cursor.execute(sql, params)
  File "/Users/sameerwadekar/miniconda3/envs/tf-mac/lib/python3.10/site-packages/django/db/backends/utils.py", line 122, in execute
    return super().execute(sql, params)
  File "/Users/sameerwadekar/miniconda3/envs/tf-mac/lib/python3.10/site-packages/django/db/backends/utils.py", line 79, in execute
    return self._execute_with_wrappers(
  File "/Users/sameerwadekar/miniconda3/envs/tf-mac/lib/python3.10/site-packages/django/db/backends/utils.py", line 92, in _execute_with_wrappers
    return executor(sql, params, many, context)
  File "/Users/sameerwadekar/miniconda3/envs/tf-mac/lib/python3.10/site-packages/django/db/backends/utils.py", line 100, in _execute
    with self.db.wrap_database_errors:
  File "/Users/sameerwadekar/miniconda3/envs/tf-mac/lib/python3.10/site-packages/django/db/utils.py", line 91, in __exit__
    raise dj_exc_value.with_traceback(traceback) from exc_value
  File "/Users/sameerwadekar/miniconda3/envs/tf-mac/lib/python3.10/site-packages/django/db/backends/utils.py", line 105, in _execute
    return self.cursor.execute(sql, params)
  File "/Users/sameerwadekar/miniconda3/envs/tf-mac/lib/python3.10/site-packages/django/db/backends/sqlite3/base.py", line 354, in execute
    return super().execute(query, params)
django.db.utils.OperationalError: no such column: api_customer.email
[15/Sep/2025 09:24:04] "GET /admin/api/customer/1/change/ HTTP/1.1" 500 181323
[15/Sep/2025 09:24:09] "GET /admin/api/customer/add/ HTTP/1.1" 200 9560
[15/Sep/2025 09:24:09] "GET /admin/jsi18n/ HTTP/1.1" 200 3342
Internal Server Error: /admin/api/customer/add/
Traceback (most recent call last):
  File "/Users/sameerwadekar/miniconda3/envs/tf-mac/lib/python3.10/site-packages/django/db/backends/utils.py", line 105, in _execute
    return self.cursor.execute(sql, params)
  File "/Users/sameerwadekar/miniconda3/envs/tf-mac/lib/python3.10/site-packages/django/db/backends/sqlite3/base.py", line 354, in execute
    return super().execute(query, params)
sqlite3.OperationalError: table api_customer has no column named email

The above exception was the direct cause of the following exception:

Traceback (most recent call last):
  File "/Users/sameerwadekar/miniconda3/envs/tf-mac/lib/python3.10/site-packages/django/core/handlers/exception.py", line 55, in inner
    response = get_response(request)
  File "/Users/sameerwadekar/miniconda3/envs/tf-mac/lib/python3.10/site-packages/django/core/handlers/base.py", line 197, in _get_response
    response = wrapped_callback(request, *callback_args, **callback_kwargs)
  File "/Users/sameerwadekar/miniconda3/envs/tf-mac/lib/python3.10/site-packages/django/contrib/admin/options.py", line 718, in wrapper
    return self.admin_site.admin_view(view)(*args, **kwargs)
  File "/Users/sameerwadekar/miniconda3/envs/tf-mac/lib/python3.10/site-packages/django/utils/decorators.py", line 188, in _view_wrapper
    result = _process_exception(request, e)
  File "/Users/sameerwadekar/miniconda3/envs/tf-mac/lib/python3.10/site-packages/django/utils/decorators.py", line 186, in _view_wrapper
    response = view_func(request, *args, **kwargs)
  File "/Users/sameerwadekar/miniconda3/envs/tf-mac/lib/python3.10/site-packages/django/views/decorators/cache.py", line 80, in _view_wrapper
    response = view_func(request, *args, **kwargs)
  File "/Users/sameerwadekar/miniconda3/envs/tf-mac/lib/python3.10/site-packages/django/contrib/admin/sites.py", line 241, in inner
    return view(request, *args, **kwargs)
  File "/Users/sameerwadekar/miniconda3/envs/tf-mac/lib/python3.10/site-packages/django/contrib/admin/options.py", line 1961, in add_view
    return self.changeform_view(request, None, form_url, extra_context)
  File "/Users/sameerwadekar/miniconda3/envs/tf-mac/lib/python3.10/site-packages/django/utils/decorators.py", line 48, in _wrapper
    return bound_method(*args, **kwargs)
  File "/Users/sameerwadekar/miniconda3/envs/tf-mac/lib/python3.10/site-packages/django/utils/decorators.py", line 188, in _view_wrapper
    result = _process_exception(request, e)
  File "/Users/sameerwadekar/miniconda3/envs/tf-mac/lib/python3.10/site-packages/django/utils/decorators.py", line 186, in _view_wrapper
    response = view_func(request, *args, **kwargs)
  File "/Users/sameerwadekar/miniconda3/envs/tf-mac/lib/python3.10/site-packages/django/contrib/admin/options.py", line 1820, in changeform_view
    return self._changeform_view(request, object_id, form_url, extra_context)
  File "/Users/sameerwadekar/miniconda3/envs/tf-mac/lib/python3.10/site-packages/django/contrib/admin/options.py", line 1871, in _changeform_view
    self.save_model(request, new_object, form, not add)
  File "/Users/sameerwadekar/miniconda3/envs/tf-mac/lib/python3.10/site-packages/django/contrib/admin/options.py", line 1294, in save_model
    obj.save()
  File "/Users/sameerwadekar/miniconda3/envs/tf-mac/lib/python3.10/site-packages/django/db/models/base.py", line 891, in save
    self.save_base(
  File "/Users/sameerwadekar/miniconda3/envs/tf-mac/lib/python3.10/site-packages/django/db/models/base.py", line 997, in save_base
    updated = self._save_table(
  File "/Users/sameerwadekar/miniconda3/envs/tf-mac/lib/python3.10/site-packages/django/db/models/base.py", line 1160, in _save_table
    results = self._do_insert(
  File "/Users/sameerwadekar/miniconda3/envs/tf-mac/lib/python3.10/site-packages/django/db/models/base.py", line 1201, in _do_insert
    return manager._insert(
  File "/Users/sameerwadekar/miniconda3/envs/tf-mac/lib/python3.10/site-packages/django/db/models/manager.py", line 87, in manager_method
    return getattr(self.get_queryset(), name)(*args, **kwargs)
  File "/Users/sameerwadekar/miniconda3/envs/tf-mac/lib/python3.10/site-packages/django/db/models/query.py", line 1847, in _insert
    return query.get_compiler(using=using).execute_sql(returning_fields)
  File "/Users/sameerwadekar/miniconda3/envs/tf-mac/lib/python3.10/site-packages/django/db/models/sql/compiler.py", line 1836, in execute_sql
    cursor.execute(sql, params)
  File "/Users/sameerwadekar/miniconda3/envs/tf-mac/lib/python3.10/site-packages/django/db/backends/utils.py", line 122, in execute
    return super().execute(sql, params)
  File "/Users/sameerwadekar/miniconda3/envs/tf-mac/lib/python3.10/site-packages/django/db/backends/utils.py", line 79, in execute
    return self._execute_with_wrappers(
  File "/Users/sameerwadekar/miniconda3/envs/tf-mac/lib/python3.10/site-packages/django/db/backends/utils.py", line 92, in _execute_with_wrappers
    return executor(sql, params, many, context)
  File "/Users/sameerwadekar/miniconda3/envs/tf-mac/lib/python3.10/site-packages/django/db/backends/utils.py", line 100, in _execute
    with self.db.wrap_database_errors:
  File "/Users/sameerwadekar/miniconda3/envs/tf-mac/lib/python3.10/site-packages/django/db/utils.py", line 91, in __exit__
    raise dj_exc_value.with_traceback(traceback) from exc_value
  File "/Users/sameerwadekar/miniconda3/envs/tf-mac/lib/python3.10/site-packages/django/db/backends/utils.py", line 105, in _execute
    return self.cursor.execute(sql, params)
  File "/Users/sameerwadekar/miniconda3/envs/tf-mac/lib/python3.10/site-packages/django/db/backends/sqlite3/base.py", line 354, in execute
    return super().execute(query, params)
django.db.utils.OperationalError: table api_customer has no column named email
[15/Sep/2025 09:24:18] "POST /admin/api/customer/add/ HTTP/1.1" 500 197232
[15/Sep/2025 09:27:07] "GET /admin/api/customer/add/ HTTP/1.1" 302 0
[15/Sep/2025 09:27:07] "GET /admin/login/?next=/admin/api/customer/add/ HTTP/1.1" 200 4194
[15/Sep/2025 09:27:07] "GET /admin/jsi18n/ HTTP/1.1" 302 0
[15/Sep/2025 09:27:07] "GET /static/admin/css/login.css HTTP/1.1" 304 0
[15/Sep/2025 09:27:09] "GET /admin/ HTTP/1.1" 302 0
[15/Sep/2025 09:27:09] "GET /admin/login/?next=/admin/ HTTP/1.1" 200 4160
[15/Sep/2025 09:27:17] "POST /admin/login/?next=/admin/ HTTP/1.1" 200 4321
[15/Sep/2025 09:27:28] "POST /admin/login/?next=/admin/ HTTP/1.1" 200 4321
[15/Sep/2025 09:29:48] "POST /admin/login/?next=/admin/ HTTP/1.1" 302 0
[15/Sep/2025 09:29:49] "GET /admin/ HTTP/1.1" 200 7227
[15/Sep/2025 09:29:49] "GET /static/admin/css/dashboard.css HTTP/1.1" 200 441
[15/Sep/2025 09:29:49] "GET /static/admin/img/icon-addlink.svg HTTP/1.1" 200 331
[15/Sep/2025 09:29:49] "GET /static/admin/img/icon-changelink.svg HTTP/1.1" 200 380
Internal Server Error: /admin/api/customer/
Traceback (most recent call last):
  File "/Users/sameerwadekar/miniconda3/envs/tf-mac/lib/python3.10/site-packages/django/db/backends/utils.py", line 105, in _execute
    return self.cursor.execute(sql, params)
  File "/Users/sameerwadekar/miniconda3/envs/tf-mac/lib/python3.10/site-packages/django/db/backends/sqlite3/base.py", line 354, in execute
    return super().execute(query, params)
sqlite3.OperationalError: no such table: api_customer

The above exception was the direct cause of the following exception:

Traceback (most recent call last):
  File "/Users/sameerwadekar/miniconda3/envs/tf-mac/lib/python3.10/site-packages/django/core/handlers/exception.py", line 55, in inner
    response = get_response(request)
  File "/Users/sameerwadekar/miniconda3/envs/tf-mac/lib/python3.10/site-packages/django/core/handlers/base.py", line 197, in _get_response
    response = wrapped_callback(request, *callback_args, **callback_kwargs)
  File "/Users/sameerwadekar/miniconda3/envs/tf-mac/lib/python3.10/site-packages/django/contrib/admin/options.py", line 718, in wrapper
    return self.admin_site.admin_view(view)(*args, **kwargs)
  File "/Users/sameerwadekar/miniconda3/envs/tf-mac/lib/python3.10/site-packages/django/utils/decorators.py", line 188, in _view_wrapper
    result = _process_exception(request, e)
  File "/Users/sameerwadekar/miniconda3/envs/tf-mac/lib/python3.10/site-packages/django/utils/decorators.py", line 186, in _view_wrapper
    response = view_func(request, *args, **kwargs)
  File "/Users/sameerwadekar/miniconda3/envs/tf-mac/lib/python3.10/site-packages/django/views/decorators/cache.py", line 80, in _view_wrapper
    response = view_func(request, *args, **kwargs)
  File "/Users/sameerwadekar/miniconda3/envs/tf-mac/lib/python3.10/site-packages/django/contrib/admin/sites.py", line 241, in inner
    return view(request, *args, **kwargs)
  File "/Users/sameerwadekar/miniconda3/envs/tf-mac/lib/python3.10/site-packages/django/utils/decorators.py", line 48, in _wrapper
    return bound_method(*args, **kwargs)
  File "/Users/sameerwadekar/miniconda3/envs/tf-mac/lib/python3.10/site-packages/django/utils/decorators.py", line 188, in _view_wrapper
    result = _process_exception(request, e)
  File "/Users/sameerwadekar/miniconda3/envs/tf-mac/lib/python3.10/site-packages/django/utils/decorators.py", line 186, in _view_wrapper
    response = view_func(request, *args, **kwargs)
  File "/Users/sameerwadekar/miniconda3/envs/tf-mac/lib/python3.10/site-packages/django/contrib/admin/options.py", line 2001, in changelist_view
    cl = self.get_changelist_instance(request)
  File "/Users/sameerwadekar/miniconda3/envs/tf-mac/lib/python3.10/site-packages/django/contrib/admin/options.py", line 866, in get_changelist_instance
    return ChangeList(
  File "/Users/sameerwadekar/miniconda3/envs/tf-mac/lib/python3.10/site-packages/django/contrib/admin/views/main.py", line 146, in __init__
    self.get_results(request)
  File "/Users/sameerwadekar/miniconda3/envs/tf-mac/lib/python3.10/site-packages/django/contrib/admin/views/main.py", line 313, in get_results
    result_count = paginator.count
  File "/Users/sameerwadekar/miniconda3/envs/tf-mac/lib/python3.10/site-packages/django/utils/functional.py", line 47, in __get__
    res = instance.__dict__[self.name] = self.func(instance)
  File "/Users/sameerwadekar/miniconda3/envs/tf-mac/lib/python3.10/site-packages/django/core/paginator.py", line 110, in count
    return c()
  File "/Users/sameerwadekar/miniconda3/envs/tf-mac/lib/python3.10/site-packages/django/db/models/query.py", line 620, in count
    return self.query.get_count(using=self.db)
  File "/Users/sameerwadekar/miniconda3/envs/tf-mac/lib/python3.10/site-packages/django/db/models/sql/query.py", line 630, in get_count
    return obj.get_aggregation(using, {"__count": Count("*")})["__count"]
  File "/Users/sameerwadekar/miniconda3/envs/tf-mac/lib/python3.10/site-packages/django/db/models/sql/query.py", line 616, in get_aggregation
    result = compiler.execute_sql(SINGLE)
  File "/Users/sameerwadekar/miniconda3/envs/tf-mac/lib/python3.10/site-packages/django/db/models/sql/compiler.py", line 1574, in execute_sql
    cursor.execute(sql, params)
  File "/Users/sameerwadekar/miniconda3/envs/tf-mac/lib/python3.10/site-packages/django/db/backends/utils.py", line 122, in execute
    return super().execute(sql, params)
  File "/Users/sameerwadekar/miniconda3/envs/tf-mac/lib/python3.10/site-packages/django/db/backends/utils.py", line 79, in execute
    return self._execute_with_wrappers(
  File "/Users/sameerwadekar/miniconda3/envs/tf-mac/lib/python3.10/site-packages/django/db/backends/utils.py", line 92, in _execute_with_wrappers
    return executor(sql, params, many, context)
  File "/Users/sameerwadekar/miniconda3/envs/tf-mac/lib/python3.10/site-packages/django/db/backends/utils.py", line 100, in _execute
    with self.db.wrap_database_errors:
  File "/Users/sameerwadekar/miniconda3/envs/tf-mac/lib/python3.10/site-packages/django/db/utils.py", line 91, in __exit__
    raise dj_exc_value.with_traceback(traceback) from exc_value
  File "/Users/sameerwadekar/miniconda3/envs/tf-mac/lib/python3.10/site-packages/django/db/backends/utils.py", line 105, in _execute
    return self.cursor.execute(sql, params)
  File "/Users/sameerwadekar/miniconda3/envs/tf-mac/lib/python3.10/site-packages/django/db/backends/sqlite3/base.py", line 354, in execute
    return super().execute(query, params)
django.db.utils.OperationalError: no such table: api_customer
[15/Sep/2025 09:29:54] "GET /admin/api/customer/ HTTP/1.1" 500 187057
[15/Sep/2025 09:30:07] "GET /admin/api/customer/add/ HTTP/1.1" 200 9560
[15/Sep/2025 09:30:07] "GET /admin/jsi18n/ HTTP/1.1" 200 3342
Internal Server Error: /admin/api/customer/add/
Traceback (most recent call last):
  File "/Users/sameerwadekar/miniconda3/envs/tf-mac/lib/python3.10/site-packages/django/db/backends/utils.py", line 105, in _execute
    return self.cursor.execute(sql, params)
  File "/Users/sameerwadekar/miniconda3/envs/tf-mac/lib/python3.10/site-packages/django/db/backends/sqlite3/base.py", line 354, in execute
    return super().execute(query, params)
sqlite3.OperationalError: no such table: api_customer

The above exception was the direct cause of the following exception:

Traceback (most recent call last):
  File "/Users/sameerwadekar/miniconda3/envs/tf-mac/lib/python3.10/site-packages/django/core/handlers/exception.py", line 55, in inner
    response = get_response(request)
  File "/Users/sameerwadekar/miniconda3/envs/tf-mac/lib/python3.10/site-packages/django/core/handlers/base.py", line 197, in _get_response
    response = wrapped_callback(request, *callback_args, **callback_kwargs)
  File "/Users/sameerwadekar/miniconda3/envs/tf-mac/lib/python3.10/site-packages/django/contrib/admin/options.py", line 718, in wrapper
    return self.admin_site.admin_view(view)(*args, **kwargs)
  File "/Users/sameerwadekar/miniconda3/envs/tf-mac/lib/python3.10/site-packages/django/utils/decorators.py", line 188, in _view_wrapper
    result = _process_exception(request, e)
  File "/Users/sameerwadekar/miniconda3/envs/tf-mac/lib/python3.10/site-packages/django/utils/decorators.py", line 186, in _view_wrapper
    response = view_func(request, *args, **kwargs)
  File "/Users/sameerwadekar/miniconda3/envs/tf-mac/lib/python3.10/site-packages/django/views/decorators/cache.py", line 80, in _view_wrapper
    response = view_func(request, *args, **kwargs)
  File "/Users/sameerwadekar/miniconda3/envs/tf-mac/lib/python3.10/site-packages/django/contrib/admin/sites.py", line 241, in inner
    return view(request, *args, **kwargs)
  File "/Users/sameerwadekar/miniconda3/envs/tf-mac/lib/python3.10/site-packages/django/contrib/admin/options.py", line 1961, in add_view
    return self.changeform_view(request, None, form_url, extra_context)
  File "/Users/sameerwadekar/miniconda3/envs/tf-mac/lib/python3.10/site-packages/django/utils/decorators.py", line 48, in _wrapper
    return bound_method(*args, **kwargs)
  File "/Users/sameerwadekar/miniconda3/envs/tf-mac/lib/python3.10/site-packages/django/utils/decorators.py", line 188, in _view_wrapper
    result = _process_exception(request, e)
  File "/Users/sameerwadekar/miniconda3/envs/tf-mac/lib/python3.10/site-packages/django/utils/decorators.py", line 186, in _view_wrapper
    response = view_func(request, *args, **kwargs)
  File "/Users/sameerwadekar/miniconda3/envs/tf-mac/lib/python3.10/site-packages/django/contrib/admin/options.py", line 1820, in changeform_view
    return self._changeform_view(request, object_id, form_url, extra_context)
  File "/Users/sameerwadekar/miniconda3/envs/tf-mac/lib/python3.10/site-packages/django/contrib/admin/options.py", line 1865, in _changeform_view
    form_validated = form.is_valid()
  File "/Users/sameerwadekar/miniconda3/envs/tf-mac/lib/python3.10/site-packages/django/forms/forms.py", line 197, in is_valid
    return self.is_bound and not self.errors
  File "/Users/sameerwadekar/miniconda3/envs/tf-mac/lib/python3.10/site-packages/django/forms/forms.py", line 192, in errors
    self.full_clean()
  File "/Users/sameerwadekar/miniconda3/envs/tf-mac/lib/python3.10/site-packages/django/forms/forms.py", line 327, in full_clean
    self._post_clean()
  File "/Users/sameerwadekar/miniconda3/envs/tf-mac/lib/python3.10/site-packages/django/forms/models.py", line 504, in _post_clean
    self.validate_unique()
  File "/Users/sameerwadekar/miniconda3/envs/tf-mac/lib/python3.10/site-packages/django/forms/models.py", line 513, in validate_unique
    self.instance.validate_unique(exclude=exclude)
  File "/Users/sameerwadekar/miniconda3/envs/tf-mac/lib/python3.10/site-packages/django/db/models/base.py", line 1377, in validate_unique
    errors = self._perform_unique_checks(unique_checks)
  File "/Users/sameerwadekar/miniconda3/envs/tf-mac/lib/python3.10/site-packages/django/db/models/base.py", line 1487, in _perform_unique_checks
    if qs.exists():
  File "/Users/sameerwadekar/miniconda3/envs/tf-mac/lib/python3.10/site-packages/django/db/models/query.py", line 1288, in exists
    return self.query.has_results(using=self.db)
  File "/Users/sameerwadekar/miniconda3/envs/tf-mac/lib/python3.10/site-packages/django/db/models/sql/query.py", line 660, in has_results
    return compiler.has_results()
  File "/Users/sameerwadekar/miniconda3/envs/tf-mac/lib/python3.10/site-packages/django/db/models/sql/compiler.py", line 1542, in has_results
    return bool(self.execute_sql(SINGLE))
  File "/Users/sameerwadekar/miniconda3/envs/tf-mac/lib/python3.10/site-packages/django/db/models/sql/compiler.py", line 1574, in execute_sql
    cursor.execute(sql, params)
  File "/Users/sameerwadekar/miniconda3/envs/tf-mac/lib/python3.10/site-packages/django/db/backends/utils.py", line 122, in execute
    return super().execute(sql, params)
  File "/Users/sameerwadekar/miniconda3/envs/tf-mac/lib/python3.10/site-packages/django/db/backends/utils.py", line 79, in execute
    return self._execute_with_wrappers(
  File "/Users/sameerwadekar/miniconda3/envs/tf-mac/lib/python3.10/site-packages/django/db/backends/utils.py", line 92, in _execute_with_wrappers
    return executor(sql, params, many, context)
  File "/Users/sameerwadekar/miniconda3/envs/tf-mac/lib/python3.10/site-packages/django/db/backends/utils.py", line 100, in _execute
    with self.db.wrap_database_errors:
  File "/Users/sameerwadekar/miniconda3/envs/tf-mac/lib/python3.10/site-packages/django/db/utils.py", line 91, in __exit__
    raise dj_exc_value.with_traceback(traceback) from exc_value
  File "/Users/sameerwadekar/miniconda3/envs/tf-mac/lib/python3.10/site-packages/django/db/backends/utils.py", line 105, in _execute
    return self.cursor.execute(sql, params)
  File "/Users/sameerwadekar/miniconda3/envs/tf-mac/lib/python3.10/site-packages/django/db/backends/sqlite3/base.py", line 354, in execute
    return super().execute(query, params)
django.db.utils.OperationalError: no such table: api_customer
[15/Sep/2025 09:30:30] "POST /admin/api/customer/add/ HTTP/1.1" 500 200924
Watching for file changes with StatReloader
[15/Sep/2025 09:34:35] "GET /admin/api/customer/add/ HTTP/1.1" 302 0
[15/Sep/2025 09:34:35] "GET /admin/login/?next=/admin/api/customer/add/ HTTP/1.1" 200 4194
[15/Sep/2025 09:34:35] "GET /admin/jsi18n/ HTTP/1.1" 302 0
[15/Sep/2025 09:34:38] "GET /admin/ HTTP/1.1" 302 0
[15/Sep/2025 09:34:38] "GET /admin/login/?next=/admin/ HTTP/1.1" 200 4160
[15/Sep/2025 09:34:38] "GET /admin/ HTTP/1.1" 302 0
[15/Sep/2025 09:34:38] "GET /admin/login/?next=/admin/ HTTP/1.1" 200 4160
[15/Sep/2025 09:34:42] "POST /admin/login/?next=/admin/ HTTP/1.1" 302 0
[15/Sep/2025 09:34:42] "GET /admin/ HTTP/1.1" 200 7227
[15/Sep/2025 09:34:46] "GET /admin/api/customer/add/ HTTP/1.1" 200 9560
[15/Sep/2025 09:34:46] "GET /admin/jsi18n/ HTTP/1.1" 200 3342
[15/Sep/2025 09:34:58] "POST /admin/api/customer/add/ HTTP/1.1" 302 0
[15/Sep/2025 09:34:58] "GET /admin/api/customer/ HTTP/1.1" 200 10398
[15/Sep/2025 09:34:58] "GET /admin/jsi18n/ HTTP/1.1" 200 3342
[15/Sep/2025 09:34:58] "GET /static/admin/img/search.svg HTTP/1.1" 200 458
[15/Sep/2025 09:35:05] "GET /admin/api/apikey/add/ HTTP/1.1" 200 11112
[15/Sep/2025 09:35:05] "GET /admin/jsi18n/ HTTP/1.1" 200 3342
[15/Sep/2025 09:35:12] "POST /admin/api/apikey/add/ HTTP/1.1" 302 0
[15/Sep/2025 09:35:12] "GET /admin/api/apikey/ HTTP/1.1" 200 10426
[15/Sep/2025 09:35:12] "GET /admin/jsi18n/ HTTP/1.1" 200 3342
/Users/sameerwadekar/Repository/HeatExchanger_Only_IOT/api/models.py changed, reloading.
Performing system checks...

System check identified no issues (0 silenced).
September 15, 2025 - 09:34:23
Django version 5.1.1, using settings 'iot_platform.settings'
Starting development server at http://0.0.0.0:8000/
Quit the server with CONTROL-C.

Watching for file changes with StatReloader
Exception in thread django-main-thread:
Traceback (most recent call last):
  File "/Users/sameerwadekar/miniconda3/envs/tf-mac/lib/python3.10/threading.py", line 1016, in _bootstrap_inner
    self.run()
  File "/Users/sameerwadekar/miniconda3/envs/tf-mac/lib/python3.10/threading.py", line 953, in run
    self._target(*self._args, **self._kwargs)
  File "/Users/sameerwadekar/miniconda3/envs/tf-mac/lib/python3.10/site-packages/django/utils/autoreload.py", line 64, in wrapper
    fn(*args, **kwargs)
  File "/Users/sameerwadekar/miniconda3/envs/tf-mac/lib/python3.10/site-packages/django/core/management/commands/runserver.py", line 134, in inner_run
    self.check(display_num_errors=True)
  File "/Users/sameerwadekar/miniconda3/envs/tf-mac/lib/python3.10/site-packages/django/core/management/base.py", line 563, in check
    raise SystemCheckError(msg)
django.core.management.base.SystemCheckError: SystemCheckError: System check identified some issues:

ERRORS:
<class 'api.admin.ApiKeyAdmin'>: (admin.E035) The value of 'readonly_fields[0]' refers to 'key', which is not a callable, an attribute of 'ApiKeyAdmin', or an attribute of 'api.ApiKey'.
<class 'api.admin.ApiKeyAdmin'>: (admin.E108) The value of 'list_display[1]' refers to 'key', which is not a callable or attribute of 'ApiKeyAdmin', or an attribute, method, or field on 'api.ApiKey'.

System check identified 2 issues (0 silenced).
/Users/sameerwadekar/Repository/HeatExchanger_Only_IOT/api/admin.py changed, reloading.
Performing system checks...

Watching for file changes with StatReloader
Watching for file changes with StatReloader
Watching for file changes with StatReloader
Error: That port is already in use.
